#VRML_SIM R2023b utf8

EXTERNPROTO "https://raw.githubusercontent.com/cyberbotics/webots/R2023b/projects/objects/backgrounds/protos/TexturedBackground.proto"
EXTERNPROTO "https://raw.githubusercontent.com/cyberbotics/webots/R2023b/projects/objects/backgrounds/protos/TexturedBackgroundLight.proto"
EXTERNPROTO "https://raw.githubusercontent.com/cyberbotics/webots/R2023b/projects/objects/floors/protos/RectangleArena.proto"
EXTERNPROTO "https://raw.githubusercontent.com/cyberbotics/webots/R2023b/projects/appearances/protos/BrushedAluminium.proto"

WorldInfo {
}
Viewpoint {
  orientation -0.2962856860961655 0.09708601723637435 0.9501521443809421 2.537941201800005
  position 1.349249045894374 -0.4090264421404099 1.1919077405008878
}
TexturedBackground {
}
TexturedBackgroundLight {
}
Robot {
  translation -0.0014362507928100514 -0.0012309169211759785 0.019570250365313742
  rotation -0.15152593977703172 0.24018920759133258 0.9588269051978751 0.012263513790795754
  children [
    DEF joint1 HingeJoint {
      jointParameters HingeJointParameters {
        position 0.5383993310505366
        axis 0 0 1
        anchor 0 0 0.04
      }
      device [
        RotationalMotor {
          name "motor1"
          minPosition -3.14
          maxPosition 3.14
          maxTorque 10000
        }
        PositionSensor {
          name "sensor1"
          resolution 0.01
        }
      ]
      endPoint Solid {
        translation 0 0 0.05
        rotation 0 0 1 0.5383993310505367
        children [
          DEF joint2 HingeJoint {
            jointParameters HingeJointParameters {
              position 0.27464716219602164
              axis 0 1 0
              anchor 0 0 0.05
            }
            device [
              RotationalMotor {
                name "motor2"
                minPosition -3.14
                maxPosition 3.14
                maxTorque 10000
              }
              PositionSensor {
                name "sensor2"
                resolution 0.01
              }
            ]
            endPoint Solid {
              translation 0.04610524781137025 0 0.2136285614562835
              rotation 0 1 0 0.27464716219602203
              children [
                DEF joint3 HingeJoint {
                  jointParameters HingeJointParameters {
                    position 2.0204928048625517
                    axis 0 1 0
                    anchor 0 0 0.22
                  }
                  device [
                    PositionSensor {
                      name "sensor3"
                      resolution 0.01
                    }
                    RotationalMotor {
                      name "motor3"
                      minPosition -3.14
                      maxPosition 3.14
                      maxTorque 10000
                    }
                  ]
                  endPoint Solid {
                    translation 0.1621042348415344 0 0.14175540244565973
                    rotation 0 1 0 2.0204928048625517
                    children [
                      HingeJoint {
                        jointParameters HingeJointParameters {
                          position 4.417487015542433e-06
                          axis 0 1 0
                          anchor 0 0 0.22
                        }
                        device [
                          PositionSensor {
                            name "sensor4"
                            resolution 0.01
                          }
                          RotationalMotor {
                            name "motor4"
                            maxTorque 10000
                          }
                        ]
                        endPoint Solid {
                          translation 0 0 0.22
                          rotation 0 1 0 3.0104771373690567e-06
                          children [
                            Solid {
                              translation -3.208e-10 -1.01632e-13 0.03
                              rotation 0.9653654670923678 0.03405581647791691 -0.258669125157133 -2.888765307179586
                              children [
                                DEF pen Pen {
                                  translation 4.5459e-09 2.23569e-10 -2.2059e-08
                                  rotation 0.00829728670379422 -0.23523290655064794 -0.9719036138985641 -1.7006453071795864
                                  children [
                                    Shape {
                                      appearance PBRAppearance {
                                      }
                                      geometry Box {
                                        size 0.01 0.01 0.05
                                      }
                                    }
                                  ]
                                  inkDensity 1
                                  write FALSE
                                }
                              ]
                              boundingObject DEF hand Shape {
                              }
                              physics Physics {
                              }
                            }
                            DEF hand Shape {
                              appearance BrushedAluminium {
                              }
                              geometry Box {
                                size 0.05 0.05 0.05
                              }
                            }
                          ]
                          boundingObject USE hand
                          physics Physics {
                          }
                        }
                      }
                      DEF arm2 Shape {
                        appearance BrushedAluminium {
                        }
                        geometry Box {
                          size 0.05 0.05 0.4
                        }
                      }
                    ]
                    boundingObject Pose {
                      children [
                        Box {
                          size 0.05 0.05 0.4
                        }
                      ]
                    }
                    physics Physics {
                      density 100
                    }
                  }
                }
                DEF arm1 Shape {
                  appearance BrushedAluminium {
                  }
                  geometry Box {
                    size 0.05 0.05 0.4
                  }
                }
              ]
              boundingObject Pose {
                children [
                  Box {
                    size 0.05 0.05 0.4
                  }
                ]
              }
              physics Physics {
                density 100
              }
            }
          }
          DEF rotate Shape {
            appearance BrushedAluminium {
            }
            geometry Box {
              size 0.05 0.05 0.05
            }
          }
        ]
        boundingObject Pose {
          children [
            Box {
              size 0.05 0.05 0.05
            }
          ]
        }
        physics Physics {
          density 100
        }
      }
    }
    DEF body Shape {
      appearance BrushedAluminium {
      }
      geometry Box {
        size 0.5 0.5 0.05
      }
    }
  ]
  boundingObject USE body
  physics Physics {
  }
  controller "my_controller"
  supervisor TRUE
}
RectangleArena {
  floorSize 5 5
}
DEF TARGET Pose {
  translation 0.375059 0.459793 0.18
  rotation 0 0 1 -0.785395307179586
  children [
    Shape {
      geometry Plane {
      }
    }
  ]
}
