<?xml version="1.0"?>
<robot name="C:/Users/sinem/OneDrive/Belgeler/my_project7/worlds/Robot.urdf" xmlns:xacro="http://ros.org/wiki/xacro">
  <link name="base_link">
    <visual>
      <geometry>
        <box size="0.5 0.5 0.05"/>
      </geometry>
    </visual>
    <collision>
      <geometry>
        <box size="0.5 0.5 0.05"/>
      </geometry>
    </collision>
  </link>
  <joint name="motor1" type="revolute">
    <parent link="base_link"/>
    <child link="solid"/>
    <axis xyz="0 0 1"/>
    <limit effort="10000" lower="-3.14" upper="3.14" velocity="10"/>
    <origin xyz="0 0 0.04" rpy="0 0 0"/>
  </joint>
  <link name="solid">
    <visual>
      <origin xyz="0 0 0.01" rpy="0 0 0"/>
      <geometry>
        <box size="0.05 0.05 0.05"/>
      </geometry>
    </visual>
    <collision>
      <origin xyz="0 0 0.01" rpy="0 0 0"/>
      <geometry>
        <box size="0.05 0.05 0.05"/>
      </geometry>
    </collision>
  </link>
  <joint name="motor2" type="revolute">
    <parent link="solid"/>
    <child link="solid_0"/>
    <axis xyz="0 1 0"/>
    <limit effort="10000" lower="-3.14" upper="3.14" velocity="10"/>
    <origin xyz="0 0 0.06" rpy="0 0 0"/>
  </joint>
  <link name="solid_0">
    <visual>
      <origin xyz="0 0 0.17" rpy="0 0 0"/>
      <geometry>
        <box size="0.05 0.05 0.4"/>
      </geometry>
    </visual>
    <collision>
      <origin xyz="0 0 0.17" rpy="0 0 0"/>
      <geometry>
        <box size="0.05 0.05 0.4"/>
      </geometry>
    </collision>
  </link>
  <joint name="motor3" type="revolute">
    <parent link="solid_0"/>
    <child link="solid_1"/>
    <axis xyz="0 1 0"/>
    <limit effort="10000" lower="-3.14" upper="3.14" velocity="10"/>
    <origin xyz="0 0 0.39" rpy="0 0 0"/>
  </joint>
  <link name="solid_1">
    <visual>
      <origin xyz="0 0 0.18" rpy="0 0 0"/>
      <geometry>
        <box size="0.05 0.05 0.4"/>
      </geometry>
    </visual>
    <collision>
      <origin xyz="0 0 0.18" rpy="0 0 0"/>
      <geometry>
        <box size="0.05 0.05 0.4"/>
      </geometry>
    </collision>
  </link>
  <joint name="motor4" type="revolute">
    <parent link="solid_1"/>
    <child link="solid_2"/>
    <axis xyz="0 1 0"/>
    <limit effort="10000" velocity="10"/>
    <origin xyz="0 0 0.34" rpy="0 0 0"/>
  </joint>
  <link name="solid_2">
    <visual>
      <origin xyz="0 0 0" rpy="0 0 0"/>
      <geometry>
        <box size="0.1 0.1 0.1"/>
      </geometry>
    </visual>
    <collision>
      <origin xyz="0 0 0" rpy="0 0 0"/>
      <geometry>
        <box size="0.1 0.1 0.1"/>
      </geometry>
    </collision>
  </link>
</robot>
